Workbook
Name EstimateInputFilingStatusCell: Estimator!$G$8
Name EstimateInputTaxYearCell: Estimator!$C$8
Name InRangeLabelCell: Parameters!$G$6
Name MaxIncomeCell: Parameters!$G$10
Name NotFoundLabelCell: Parameters!$G$8
Name OutOfRangeLabelCell: Parameters!$G$7
Name SelectionValidLabelCell: Parameters!$G$9

Sheet ReadMe
B3: Purpose
B4: This spreadsheet helps you quickly estimate your total federal tax liability by combining the most common tax types for employed individuals in one place. Key benefit of this calculator: Most tax estimators focus on only one tax type (e.g., income tax). This tool calculates and properly combines most common tax types: - Federal Income Tax (including Alternative Minimum Tax (AMT)) - Long-Term Capital Gains Tax - Social Security Tax - Medicare Taxes (including Additional Medicare Tax and NIIT) Philosophy: This is an estimation tool, not a precise calculator. It intentionally omits some deductions to keep things simple. It's better to slightly overestimate (and get a refund) than underestimate (and face penalties).
B6: How to use
B7: 1. If you are viewing the public read-only version, get your own private copy of the calculator: - Go to: File > Create a Copy. To use with Excel for Desktop (Windows or Mac), select 'Download a Copy'. To use with Excel Online (free), select 'Create a copy online'. - Alternatively, download the calculator Excel file directly from the GitHub repo (link below). 2. Input Your Income ('Estomator' tab, orange cells only): - Enter your estimated income in section 'Your extimated income'. - Each income category has 3 input fields. Use them however you like (they're simply added together). - Only edit orange cells. All other cells are auto-computed. - Some input cells are pre-filled with sample values. Make sure to override with your values. 3. Review Your Results: - 'Total Tax Summary' section: View estimated tax by type and your total. - Detail sections below: See exactly how each tax is calculated. - 'Parameters' tab: Reference tax rates and brackets for each year.
B8: Link to this calculator on GitHub:
B9: https://github.com/macrogreg/Combined-Income-Tax-Estimator
B11: Tax types not considered
B12: - State and local taxes. - Some nuances of Alternative Minimum Tax (AMT), such as Incentive Stock Options (ISO) exercise tax. This can significantly impact the AMT. There may be other AMT nuances that are not considered. - Self-Employment Tax. - There may be others, so focus on what is explicitly covered (see above).
B15: ⚠️ This calculator is not a qualified tax advice.
B16: This tool is for estimation purposes only. It should be reasonably accurate for ~90% of employed individuals. The calculator accounts for common income types, such as W-2, capital gains, rental income, and others. For fully reliable tax calculations, expecially for complex tax situations, always consult a qualified tax professional!

Sheet Estimator
B2: * All calculated values are estimates. | F2: Select/enter values for orange fields.
B3: The author is not a qualified tax expert. | F3: Do not modify other fields (auto-computed).
B5: Your extimated income
B6: Enter your income in this section. Tax estimates will be based on it.
B8: Tax Year: | C8: 2025 | F8: Filing Status: | G8: Single
B10: Earned Income | F10: Deductions towards Adjusted Gross Income (AGI) | J10: Regular Income Tax Deductions
B11: e.g., wages, tips, bonuses, benefits, shares, … | F11: e.g., certain 401k, IRA & HSA contributions, certain education expenses, certain other expenses | J11: below-the-line items: use standard OR itemize, e.g., mortgage interest, charity, state & local taxes, …
B13: Gross Wages A: | C13: 80000 | F13: AGI above-the-line Deductions A: | G13: 5000 | J13: The larger option will be used:
B14: Gross Wages B: | C14: 0 | F14: AGI above-the-line Deductions B: | G14: 0 | J14: Standard Deduction for selected status: | K14: =_xlfn.XLOOKUP(TRUE, StandardDeductionAmountTable[IsSelected], StandardDeductionAmountTable[Standard Deduction Amount], NotFoundLabelCell) -> 15000
B15: Gross Wages C: | C15: 0 | F15: AGI above-the-line Deductions C: | G15: 0 | J15: Itemized Deductions total: | K15: 0 | L15: (leave $0, if not itemizing)
B16: Total Gross Wages: | C16: =SUM(C13:C15) -> 80000 | D16: =IF( AND(0 <= C16, C16 <= MaxIncomeCell), InRangeLabelCell, OutOfRangeLabelCell ) -> ✔ | F16: Total AGI above-the-line Deductions: | G16: =SUM(G13:G15) -> 5000 | H16: =IF( AND(0 <= G16, G16 <= MaxIncomeCell), InRangeLabelCell, OutOfRangeLabelCell ) -> ✔ | J16: Deduction Amount: | K16: =MAX(K14:K15) -> 15000
B19: Passive Income & Similar | F19: Long-term Capital Gains | J19: Short-term Capital Gains
B20: e.g., rental income, interest, non-qualified dividends, … | F20: e.g., qualidied dividends, realized income from sold assets | J20: e.g., realized income from sold short-term assets
B22: Net Rental & similar Income A: | C22: 10000 | F22: Long-term Capital Gains A: | G22: 5000 | J22: Short-term Capital Gains A: | K22: 2000
B23: Net Rental & similar Income B: | C23: 0 | F23: Long-term Capital Gains B: | G23: 0 | J23: Short-term Capital Gains B: | K23: 0
B24: Net Rental & similar Income C: | C24: 0 | F24: Long-term Capital Gains C: | G24: 0 | J24: Short-term Capital Gains C: | K24: 0
B25: Total Rental & similar Income: | C25: =SUM(C22:C24) -> 10000 | D25: =IF( AND(0 <= C25, C25 <= MaxIncomeCell), InRangeLabelCell, OutOfRangeLabelCell ) -> ✔ | F25: Total Long-term Capital Gains: | G25: =SUM(G22:G24) -> 5000 | H25: =IF( AND(0 <= G25, G25 <= MaxIncomeCell), InRangeLabelCell, OutOfRangeLabelCell ) -> ✔ | J25: Total Short-term Capital Gains: | K25: =SUM(K22:K24) -> 2000 | L25: =IF( AND(0 <= K25, K25 <= MaxIncomeCell), InRangeLabelCell, OutOfRangeLabelCell ) -> ✔
B28: Income Summary
B29: This section summarizes your income entered above.
B31: Gross Income | F31: Adjusted Gross Income (AGI)
B33: =$B$16 -> Total Gross Wages: | C33: =$C$16 -> 80000 | D33: =_xlfn.LET( _xlpm.FormulaText, _xlfn.FORMULATEXT(C33), HYPERLINK( "#" & SUBSTITUTE(_xlpm.FormulaText, "=", ""), _xlpm.FormulaText ) ) -> = $C$16 | F33: =$B$16 -> Total Gross Wages: | G33: =$C$16 -> 80000 | H33: =_xlfn.LET( _xlpm.FormulaText, _xlfn.FORMULATEXT(G33), HYPERLINK( "#" & SUBSTITUTE(_xlpm.FormulaText, "=", ""), _xlpm.FormulaText ) ) -> = $C$16
B34: =$B$25 -> Total Rental & similar Income: | C34: =$C$25 -> 10000 | D34: =_xlfn.LET( _xlpm.FormulaText, _xlfn.FORMULATEXT(C34), HYPERLINK( "#" & SUBSTITUTE(_xlpm.FormulaText, "=", ""), _xlpm.FormulaText ) ) -> = $C$25 | F34: =$B$25 -> Total Rental & similar Income: | G34: =$C$25 -> 10000 | H34: =_xlfn.LET( _xlpm.FormulaText, _xlfn.FORMULATEXT(G34), HYPERLINK( "#" & SUBSTITUTE(_xlpm.FormulaText, "=", ""), _xlpm.FormulaText ) ) -> = $C$25
B35: =$F$25 -> Total Long-term Capital Gains: | C35: =$G$25 -> 5000 | D35: =_xlfn.LET( _xlpm.FormulaText, _xlfn.FORMULATEXT(C35), HYPERLINK( "#" & SUBSTITUTE(_xlpm.FormulaText, "=", ""), _xlpm.FormulaText ) ) -> = $G$25 | F35: =$F$25 -> Total Long-term Capital Gains: | G35: =$G$25 -> 5000 | H35: =_xlfn.LET( _xlpm.FormulaText, _xlfn.FORMULATEXT(G35), HYPERLINK( "#" & SUBSTITUTE(_xlpm.FormulaText, "=", ""), _xlpm.FormulaText ) ) -> = $G$25
B36: =$J$25 -> Total Short-term Capital Gains: | C36: =$K$25 -> 2000 | D36: =_xlfn.LET( _xlpm.FormulaText, _xlfn.FORMULATEXT(C36), HYPERLINK( "#" & SUBSTITUTE(_xlpm.FormulaText, "=", ""), _xlpm.FormulaText ) ) -> = $K$25 | F36: =$J$25 -> Total Short-term Capital Gains: | G36: =$K$25 -> 2000 | H36: =_xlfn.LET( _xlpm.FormulaText, _xlfn.FORMULATEXT(G36), HYPERLINK( "#" & SUBSTITUTE(_xlpm.FormulaText, "=", ""), _xlpm.FormulaText ) ) -> = $K$25
B37: Total Gross Income: | C37: =SUM(C33:C36) -> 97000 | D37: =IF( AND(0 <= C37, C37 <= MaxIncomeCell), InRangeLabelCell, OutOfRangeLabelCell ) -> ✔ | F37: =$F$16 -> Total AGI above-the-line Deductions: | G37: =- $G$16 -> -5000 | H37: =_xlfn.LET( _xlpm.FormulaText, _xlfn.FORMULATEXT(G37), HYPERLINK( "#" & SUBSTITUTE(SUBSTITUTE(_xlpm.FormulaText, "-", ""), "=", ""), _xlpm.FormulaText ) ) -> = - $G$16
F38: Total AGI (Adjusted Gross Income): | G38: =SUM(G33:G37) -> 92000 | H38: =IF( AND(0 <= G38, G38 <= MaxIncomeCell), InRangeLabelCell, OutOfRangeLabelCell ) -> ✔
B40: Total Tax Summary
B41: This is the result section. It summarizes your estimated taxes.
B43: Total Tax Estimate | F43: Total Net Income Estimate
B45: Tax Type | C45: Amount | F45: =$B$37 -> Total Gross Income: | G45: =$C$37 -> 97000 | H45: =_xlfn.LET( _xlpm.FormulaText, _xlfn.FORMULATEXT(G45), HYPERLINK( "#" & SUBSTITUTE(_xlpm.FormulaText, "=", ""), _xlpm.FormulaText ) ) -> = $C$37
B46: =$J$73 -> Effective Federal Income Tax | C46: =$K$78 -> 10754 | D46: =_xlfn.LET( _xlpm.FormulaText, _xlfn.FORMULATEXT(C46), HYPERLINK( "#" & SUBSTITUTE(_xlpm.FormulaText, "=", ""), _xlpm.FormulaText ) ) -> = $K$78 | F46: =TotalTaxEstimateTable[[#Totals],[Tax Type]] -> Total Tax Estimate: | G46: =TotalTaxEstimateTable[[#Totals],[Amount]] -> 17624
B47: =B103 -> Long Term Capital Gain Tax (LTCG) | C47: =$C$121 -> 750 | D47: =_xlfn.LET( _xlpm.FormulaText, _xlfn.FORMULATEXT(C47), HYPERLINK( "#" & SUBSTITUTE(_xlpm.FormulaText, "=", ""), _xlpm.FormulaText ) ) -> = $C$121 | F47: Total tax as percentage of Income: | G47: =G46 / G45 -> 0.18169072 | H47: =_xlfn.LET( _xlpm.FormulaText, _xlfn.FORMULATEXT(G47), _xlpm.FormulaText ) -> = G46 / G45
B48: =$J$57 -> Social Security Tax | C48: =$K$64 -> 4960 | D48: =_xlfn.LET( _xlpm.FormulaText, _xlfn.FORMULATEXT(C48), HYPERLINK( "#" & SUBSTITUTE(_xlpm.FormulaText, "=", ""), _xlpm.FormulaText ) ) -> = $K$64 | F48: Net Income Estimate | G48: =G45 - G46 -> 79376 | H48: =_xlfn.LET( _xlpm.FormulaText, _xlfn.FORMULATEXT(G48), _xlpm.FormulaText ) -> = G45 - G46
B49: =$B$57 -> Medicare Wages Tax | C49: =$C$67 -> 1160 | D49: =_xlfn.LET( _xlpm.FormulaText, _xlfn.FORMULATEXT(C49), HYPERLINK( "#" & SUBSTITUTE(_xlpm.FormulaText, "=", ""), _xlpm.FormulaText ) ) -> = $C$67
B50: =$F$57 -> Medicare Net Investment Income Tax (NIIT) | C50: =$G$68 -> 0 | D50: =_xlfn.LET( _xlpm.FormulaText, _xlfn.FORMULATEXT(C50), HYPERLINK( "#" & SUBSTITUTE(_xlpm.FormulaText, "=", ""), _xlpm.FormulaText ) ) -> = $G$68
B51: Total Tax Estimate: | C51: =SUBTOTAL(109,TotalTaxEstimateTable[Amount]) -> 17624
B55: Federal Insurance Contributions & Affordable Care Act Taxes
B57: Medicare Wages Tax | F57: Medicare Net Investment Income Tax (NIIT) | J57: Social Security Tax
B59: Taxable Medicare Wages Amount: | C59: =$C$16 -> 80000 | D59: =_xlfn.LET( _xlpm.FormulaText, _xlfn.FORMULATEXT(C59), HYPERLINK( "#" & SUBSTITUTE(_xlpm.FormulaText, "=", ""), _xlpm.FormulaText ) ) -> = $C$16 | F59: Net Investment Amount: | G59: =$C$25 + $G$25 + $K$25 -> 17000 | H59: =IF( AND(0 <= G59, G59 <= MaxIncomeCell), InRangeLabelCell, OutOfRangeLabelCell ) -> ✔ | J59: Max Taxable Amount: | K59: =_xlfn.XLOOKUP(TRUE, SocialSecurityTaxRateTable[IsSelected], SocialSecurityTaxRateTable[Max Taxable Income], NotFoundLabelCell) -> 176100 | L59: {=_xlfn.LET( _xlpm.LookupTableName, "SocialSecurityTaxRateTable", _xlpm.ValueColumnName, "Max Taxable Income", _xlpm.TableValueColumn, INDIRECT(_xlpm.LookupTableName & "[" & _xlpm.ValueColumnName & "]"), _xlpm.TableRowNum, _xlfn.XMATCH(TRUE, INDIRECT(_xlpm.LookupTableName & "[IsSelected]")), _xlpm.LinkTarget, IF(ISNA(_xlpm.TableRowNum), "#" & CELL("address", L59), "#" & CELL("address", INDEX(_xlpm.TableValueColumn, _xlpm.TableRowNum)) ), _xlpm.LinkLabel, IF(ISNA(_xlpm.TableRowNum), NotFoundLabelCell, "in " & _xlpm.LookupTableName ), HYPERLINK(_xlpm.LinkTarget, _xlpm.LinkLabel) )} -> in SocialSecurityTaxRateTable
F60: Applicable Modified Adjusted Gross Income (MAGI): | G60: =$C$37 -> 97000 | H60: =_xlfn.LET( _xlpm.FormulaText, _xlfn.FORMULATEXT(G60), HYPERLINK( "#" & SUBSTITUTE(_xlpm.FormulaText, "=", ""), _xlpm.FormulaText ) ) -> = $C$37
...

Sheet Parameters
B2: This tab contains the tax computation parameters for different Tax Years, Income Brackets, and Filing Satuses.
B3: The `IsSelected` columns are auto-populated based on the inputs on the `Estimator` tab.
B6: =_xlfn.LET( _xlpm.HandleFormulaText, _xlfn.FORMULATEXT(D6), MID(_xlpm.HandleFormulaText, 2, FIND("[", _xlpm.HandleFormulaText) - 2) ) -> FilingStatusTable | C6: Handle: | D6: =FilingStatusTable[[#Headers],[Filing Status]] -> Filing Status | F6: In Range Label: | G6: ✔
C7: =_xlfn.LET( _xlpm.CountSelected, COUNTIF(FilingStatusTable[IsSelected], TRUE), IF( _xlpm.CountSelected = 1, SelectionValidLabelCell, "Error: " & _xlpm.CountSelected & " rows selected") ) -> Valid | F7: Out Of Range Label: | G7: OutOfRange
B8: Filing Status | C8: IsSelected | F8: Not Found Label: | G8: Not Found
B9: Single | C9: =(FilingStatusTable[[#This Row],[Filing Status]] = EstimateInputFilingStatusCell) -> TRUE | F9: Selection Valid Label: | G9: Valid
B10: Married Filing Jointly | C10: =(FilingStatusTable[[#This Row],[Filing Status]] = EstimateInputFilingStatusCell) -> FALSE | F10: Max Income: | G10: 10000000
B11: Married Filing Separately | C11: =(FilingStatusTable[[#This Row],[Filing Status]] = EstimateInputFilingStatusCell) -> FALSE
B12: Head of Household | C12: =(FilingStatusTable[[#This Row],[Filing Status]] = EstimateInputFilingStatusCell) -> FALSE
F14: =_xlfn.LET( _xlpm.HandleFormulaText, _xlfn.FORMULATEXT(H14), MID(_xlpm.HandleFormulaText, 2, FIND("[", _xlpm.HandleFormulaText) - 2) ) -> MedicareWageTaxRateTable | G14: Handle: | H14: =MedicareWageTaxRateTable[[#Headers],[Medicare Rate]] -> Medicare Rate
L15: =_xlfn.LET( _xlpm.CountSelected, COUNTIF(MedicareWageTaxRateTable[IsSelected], TRUE), IF( _xlpm.CountSelected = 1, SelectionValidLabelCell, "Error: " & _xlpm.CountSelected & " rows selected") ) -> Valid
B16: =_xlfn.LET( _xlpm.HandleFormulaText, _xlfn.FORMULATEXT(D16), MID(_xlpm.HandleFormulaText, 2, FIND("[", _xlpm.HandleFormulaText) - 2) ) -> SupportedYearsTable | C16: Handle: | D16: =SupportedYearsTable[[#Headers],[Tax Year]] -> Tax Year | F16: Filing Status | G16: Tax Year | H16: Medicare Rate | I16: RangeStart | J16: RangeEnd | K16: SumLowerRanges | L16: IsSelected
C17: =_xlfn.LET( _xlpm.CountSelected, COUNTIF(SupportedYearsTable[IsSelected], TRUE), IF( _xlpm.CountSelected = 1, SelectionValidLabelCell, "Error: " & _xlpm.CountSelected & " rows selected") ) -> Valid | F17: Single | G17: 2024 | H17: 0.0145 | I17: 0 | J17: 200000 | K17: 0 | L17: =AND( (MedicareWageTaxRateTable[[#This Row],[Tax Year]] = EstimateInputTaxYearCell), (MedicareWageTaxRateTable[[#This Row],[Filing Status]] = EstimateInputFilingStatusCell), (MedicareWageTaxRateTable[[#This Row],[RangeStart]] < Estimator!$C$59), (MedicareWageTaxRateTable[[#This Row],[RangeEnd]] >= Estimator!$C$59) ) -> FALSE
B18: Tax Year | C18: IsSelected | F18: Single | G18: 2024 | H18: =$H17 + 0.009 -> 0.0235 | I18: =$J17 -> 200000 | J18: =MaxIncomeCell -> 10000000 | K18: =$J17*$H17 -> 2900 | L18: =AND( (MedicareWageTaxRateTable[[#This Row],[Tax Year]] = EstimateInputTaxYearCell), (MedicareWageTaxRateTable[[#This Row],[Filing Status]] = EstimateInputFilingStatusCell), (MedicareWageTaxRateTable[[#This Row],[RangeStart]] < Estimator!$C$59), (MedicareWageTaxRateTable[[#This Row],[RangeEnd]] >= Estimator!$C$59) ) -> FALSE
B19: 2024 | C19: =(SupportedYearsTable[[#This Row],[Tax Year]] = EstimateInputTaxYearCell) -> FALSE | F19: Married Filing Jointly | G19: 2024 | H19: 0.0145 | I19: 0 | J19: 250000 | K19: 0 | L19: =AND( (MedicareWageTaxRateTable[[#This Row],[Tax Year]] = EstimateInputTaxYearCell), (MedicareWageTaxRateTable[[#This Row],[Filing Status]] = EstimateInputFilingStatusCell), (MedicareWageTaxRateTable[[#This Row],[RangeStart]] < Estimator!$C$59), (MedicareWageTaxRateTable[[#This Row],[RangeEnd]] >= Estimator!$C$59) ) -> FALSE
B20: 2025 | C20: =(SupportedYearsTable[[#This Row],[Tax Year]] = EstimateInputTaxYearCell) -> TRUE | F20: Married Filing Jointly | G20: 2024 | H20: =$H19 + 0.009 -> 0.0235 | I20: =$J19 -> 250000 | J20: =MaxIncomeCell -> 10000000 | K20: =$J19*$H19 -> 3625 | L20: =AND( (MedicareWageTaxRateTable[[#This Row],[Tax Year]] = EstimateInputTaxYearCell), (MedicareWageTaxRateTable[[#This Row],[Filing Status]] = EstimateInputFilingStatusCell), (MedicareWageTaxRateTable[[#This Row],[RangeStart]] < Estimator!$C$59), (MedicareWageTaxRateTable[[#This Row],[RangeEnd]] >= Estimator!$C$59) ) -> FALSE
F21: Married Filing Separately | G21: 2024 | H21: 0.0145 | I21: 0 | J21: 125000 | K21: 0 | L21: =AND( (MedicareWageTaxRateTable[[#This Row],[Tax Year]] = EstimateInputTaxYearCell), (MedicareWageTaxRateTable[[#This Row],[Filing Status]] = EstimateInputFilingStatusCell), (MedicareWageTaxRateTable[[#This Row],[RangeStart]] < Estimator!$C$59), (MedicareWageTaxRateTable[[#This Row],[RangeEnd]] >= Estimator!$C$59) ) -> FALSE
F22: Married Filing Separately | G22: 2024 | H22: =$H21 + 0.009 -> 0.0235 | I22: =$J21 -> 125000 | J22: =MaxIncomeCell -> 10000000 | K22: =$J21*$H21 -> 1812.5 | L22: =AND( (MedicareWageTaxRateTable[[#This Row],[Tax Year]] = EstimateInputTaxYearCell), (MedicareWageTaxRateTable[[#This Row],[Filing Status]] = EstimateInputFilingStatusCell), (MedicareWageTaxRateTable[[#This Row],[RangeStart]] < Estimator!$C$59), (MedicareWageTaxRateTable[[#This Row],[RangeEnd]] >= Estimator!$C$59) ) -> FALSE
F23: Head of Household | G23: 2024 | H23: 0.0145 | I23: 0 | J23: 200000 | K23: 0 | L23: =AND( (MedicareWageTaxRateTable[[#This Row],[Tax Year]] = EstimateInputTaxYearCell), (MedicareWageTaxRateTable[[#This Row],[Filing Status]] = EstimateInputFilingStatusCell), (MedicareWageTaxRateTable[[#This Row],[RangeStart]] < Estimator!$C$59), (MedicareWageTaxRateTable[[#This Row],[RangeEnd]] >= Estimator!$C$59) ) -> FALSE
F24: Head of Household | G24: 2024 | H24: =$H23 + 0.009 -> 0.0235 | I24: =$J23 -> 200000 | J24: =MaxIncomeCell -> 10000000 | K24: =$J23*$H23 -> 2900 | L24: =AND( (MedicareWageTaxRateTable[[#This Row],[Tax Year]] = EstimateInputTaxYearCell), (MedicareWageTaxRateTable[[#This Row],[Filing Status]] = EstimateInputFilingStatusCell), (MedicareWageTaxRateTable[[#This Row],[RangeStart]] < Estimator!$C$59), (MedicareWageTaxRateTable[[#This Row],[RangeEnd]] >= Estimator!$C$59) ) -> FALSE
L25: =AND( (MedicareWageTaxRateTable[[#This Row],[Tax Year]] = EstimateInputTaxYearCell), (MedicareWageTaxRateTable[[#This Row],[Filing Status]] = EstimateInputFilingStatusCell), (MedicareWageTaxRateTable[[#This Row],[RangeStart]] < Estimator!$C$59), (MedicareWageTaxRateTable[[#This Row],[RangeEnd]] >= Estimator!$C$59) ) -> FALSE
F26: Single | G26: 2025 | H26: 0.0145 | I26: 0 | J26: 200000 | K26: 0 | L26: =AND( (MedicareWageTaxRateTable[[#This Row],[Tax Year]] = EstimateInputTaxYearCell), (MedicareWageTaxRateTable[[#This Row],[Filing Status]] = EstimateInputFilingStatusCell), (MedicareWageTaxRateTable[[#This Row],[RangeStart]] < Estimator!$C$59), (MedicareWageTaxRateTable[[#This Row],[RangeEnd]] >= Estimator!$C$59) ) -> TRUE
F27: Single | G27: 2025 | H27: =$H26 + 0.009 -> 0.0235 | I27: =$J26 -> 200000 | J27: =MaxIncomeCell -> 10000000 | K27: =$J26*$H26 -> 2900 | L27: =AND( (MedicareWageTaxRateTable[[#This Row],[Tax Year]] = EstimateInputTaxYearCell), (MedicareWageTaxRateTable[[#This Row],[Filing Status]] = EstimateInputFilingStatusCell), (MedicareWageTaxRateTable[[#This Row],[RangeStart]] < Estimator!$C$59), (MedicareWageTaxRateTable[[#This Row],[RangeEnd]] >= Estimator!$C$59) ) -> FALSE
F28: Married Filing Jointly | G28: 2025 | H28: 0.0145 | I28: 0 | J28: 250000 | K28: 0 | L28: =AND( (MedicareWageTaxRateTable[[#This Row],[Tax Year]] = EstimateInputTaxYearCell), (MedicareWageTaxRateTable[[#This Row],[Filing Status]] = EstimateInputFilingStatusCell), (MedicareWageTaxRateTable[[#This Row],[RangeStart]] < Estimator!$C$59), (MedicareWageTaxRateTable[[#This Row],[RangeEnd]] >= Estimator!$C$59) ) -> FALSE
F29: Married Filing Jointly | G29: 2025 | H29: =$H28 + 0.009 -> 0.0235 | I29: =$J28 -> 250000 | J29: =MaxIncomeCell -> 10000000 | K29: =$J28*$H28 -> 3625 | L29: =AND( (MedicareWageTaxRateTable[[#This Row],[Tax Year]] = EstimateInputTaxYearCell), (MedicareWageTaxRateTable[[#This Row],[Filing Status]] = EstimateInputFilingStatusCell), (MedicareWageTaxRateTable[[#This Row],[RangeStart]] < Estimator!$C$59), (MedicareWageTaxRateTable[[#This Row],[RangeEnd]] >= Estimator!$C$59) ) -> FALSE
F30: Married Filing Separately | G30: 2025 | H30: 0.0145 | I30: 0 | J30: 125000 | K30: 0 | L30: =AND( (MedicareWageTaxRateTable[[#This Row],[Tax Year]] = EstimateInputTaxYearCell), (MedicareWageTaxRateTable[[#This Row],[Filing Status]] = EstimateInputFilingStatusCell), (MedicareWageTaxRateTable[[#This Row],[RangeStart]] < Estimator!$C$59), (MedicareWageTaxRateTable[[#This Row],[RangeEnd]] >= Estimator!$C$59) ) -> FALSE
F31: Married Filing Separately | G31: 2025 | H31: =$H30 + 0.009 -> 0.0235 | I31: =$J30 -> 125000 | J31: =MaxIncomeCell -> 10000000 | K31: =$J30*$H30 -> 1812.5 | L31: =AND( (MedicareWageTaxRateTable[[#This Row],[Tax Year]] = EstimateInputTaxYearCell), (MedicareWageTaxRateTable[[#This Row],[Filing Status]] = EstimateInputFilingStatusCell), (MedicareWageTaxRateTable[[#This Row],[RangeStart]] < Estimator!$C$59), (MedicareWageTaxRateTable[[#This Row],[RangeEnd]] >= Estimator!$C$59) ) -> FALSE
F32: Head of Household | G32: 2025 | H32: 0.0145 | I32: 0 | J32: 200000 | K32: 0 | L32: =AND( (MedicareWageTaxRateTable[[#This Row],[Tax Year]] = EstimateInputTaxYearCell), (MedicareWageTaxRateTable[[#This Row],[Filing Status]] = EstimateInputFilingStatusCell), (MedicareWageTaxRateTable[[#This Row],[RangeStart]] < Estimator!$C$59), (MedicareWageTaxRateTable[[#This Row],[RangeEnd]] >= Estimator!$C$59) ) -> FALSE
F33: Head of Household | G33: 2025 | H33: =$H32 + 0.009 -> 0.0235 | I33: =$J32 -> 200000 | J33: =MaxIncomeCell -> 10000000 | K33: =$J32*$H32 -> 2900 | L33: =AND( (MedicareWageTaxRateTable[[#This Row],[Tax Year]] = EstimateInputTaxYearCell), (MedicareWageTaxRateTable[[#This Row],[Filing Status]] = EstimateInputFilingStatusCell), (MedicareWageTaxRateTable[[#This Row],[RangeStart]] < Estimator!$C$59), (MedicareWageTaxRateTable[[#This Row],[RangeEnd]] >= Estimator!$C$59) ) -> FALSE
F37: =_xlfn.LET( _xlpm.HandleFormulaText, _xlfn.FORMULATEXT(H37), MID(_xlpm.HandleFormulaText, 2, FIND("[", _xlpm.HandleFormulaText) - 2) ) -> MedicareNetInvestIncomeTaxTable | G37: Handle: | H37: =MedicareNetInvestIncomeTaxTable[[#Headers],[NetInvestInc Rate]] -> NetInvestInc Rate
J38: =_xlfn.LET( _xlpm.CountSelected, COUNTIF(MedicareNetInvestIncomeTaxTable[IsSelected], TRUE), IF( _xlpm.CountSelected = 1, SelectionValidLabelCell, "Error: " & _xlpm.CountSelected & " rows selected") ) -> Valid
F39: Status LabelId | G39: Tax Year | H39: NetInvestInc Rate | I39: Modified AGI Threshold | J39: IsSelected
F40: Single | G40: 2024 | H40: 0.038 | I40: 200000 | J40: =AND( (MedicareNetInvestIncomeTaxTable[[#This Row],[Tax Year]] = EstimateInputTaxYearCell), (MedicareNetInvestIncomeTaxTable[[#This Row],[Status LabelId]] = EstimateInputFilingStatusCell) ) -> FALSE
F41: Married Filing Jointly | G41: 2024 | H41: 0.038 | I41: 250000 | J41: =AND( (MedicareNetInvestIncomeTaxTable[[#This Row],[Tax Year]] = EstimateInputTaxYearCell), (MedicareNetInvestIncomeTaxTable[[#This Row],[Status LabelId]] = EstimateInputFilingStatusCell) ) -> FALSE
F42: Married Filing Separately | G42: 2024 | H42: 0.038 | I42: 125000 | J42: =AND( (MedicareNetInvestIncomeTaxTable[[#This Row],[Tax Year]] = EstimateInputTaxYearCell), (MedicareNetInvestIncomeTaxTable[[#This Row],[Status LabelId]] = EstimateInputFilingStatusCell) ) -> FALSE
F43: Head of Household | G43: 2024 | H43: 0.038 | I43: 200000 | J43: =AND( (MedicareNetInvestIncomeTaxTable[[#This Row],[Tax Year]] = EstimateInputTaxYearCell), (MedicareNetInvestIncomeTaxTable[[#This Row],[Status LabelId]] = EstimateInputFilingStatusCell) ) -> FALSE
J44: =AND( (MedicareNetInvestIncomeTaxTable[[#This Row],[Tax Year]] = EstimateInputTaxYearCell), (MedicareNetInvestIncomeTaxTable[[#This Row],[Status LabelId]] = EstimateInputFilingStatusCell) ) -> FALSE
F45: Single | G45: 2025 | H45: 0.038 | I45: 200000 | J45: =AND( (MedicareNetInvestIncomeTaxTable[[#This Row],[Tax Year]] = EstimateInputTaxYearCell), (MedicareNetInvestIncomeTaxTable[[#This Row],[Status LabelId]] = EstimateInputFilingStatusCell) ) -> TRUE
F46: Married Filing Jointly | G46: 2025 | H46: 0.038 | I46: 250000 | J46: =AND( (MedicareNetInvestIncomeTaxTable[[#This Row],[Tax Year]] = EstimateInputTaxYearCell), (MedicareNetInvestIncomeTaxTable[[#This Row],[Status LabelId]] = EstimateInputFilingStatusCell) ) -> FALSE
F47: Married Filing Separately | G47: 2025 | H47: 0.038 | I47: 125000 | J47: =AND( (MedicareNetInvestIncomeTaxTable[[#This Row],[Tax Year]] = EstimateInputTaxYearCell), (MedicareNetInvestIncomeTaxTable[[#This Row],[Status LabelId]] = EstimateInputFilingStatusCell) ) -> FALSE
...
